<robot name="mycar">
    <link name="base_link">
        <visual>
            <geometry>
                <cylinder radius="0.27" length="0.06"/>
            </geometry>
            <material name="white">
                <color rgba="1 1 1 1"/>
            </material>
        </visual>
    </link>

    <link name="right">
        <visual>
            <origin rpy="0.0 1.57 0.0"/>
            <geometry>
                <cylinder radius="0.07" length="0.04"/>
            </geometry>
            <material name="black">
                <color rgba="0 0 0 1"/>
            </material>
        </visual>
    </link>

    <link name="left">
        <visual>
            <origin rpy="0.0 1.57 0.0"/>
            <geometry>
                <cylinder radius="0.07" length="0.04"/>
            </geometry>
            <material name="black">
                <color rgba="0 0 0 1"/>
            </material>
        </visual>
    </link>

    <link name="rplidar">
        <inertial>
            <origin rpy="0.0 0.0 0.0" xyz="0.0 0.0 0.0"/>
            <mass value="1e-5"/>
            <inertia ixx="1e-6" ixy="0.0" ixz="0.0" iyy="1e-6" iyz="0.0" izz="1e-6"/>
        </inertial>
        <visual>
            <origin xyz="0.0 0.0 0.0" rpy="0.0 0.0 0.0"/>
            <geometry>
                <mesh filename="package://urdf_demo/urdf/rplidar.dae" />
            </geometry>
        </visual>
        <collision>
            <origin rpy="0.0 0.0 0.0" xyz="0.0 0.0 0.0"/>
            <geometry>
                <cylinder radius="0.035" length="0.04"/>
            </geometry>
        </collision>
    </link>

    <joint name="right" type="continuous">
        <origin rpy="0.0 0.0 1.57" xyz="0.0 -0.3 0"/>
        <parent link="base_link"/>
        <child link="right"/>
    </joint>

    <joint name="left" type="continuous">
        <origin rpy="0.0 0.0 1.57" xyz="0.0 0.3 0"/>
        <parent link="base_link"/>
        <child link="left"/>
    </joint>

    <joint name="rplidar_joint" type="fixed">
        <axis xyz="0 1 0"/>
        <origin xyz="0.2 0 0.12"/>
        <parent link="base_link"/>
        <child link="rplidar"/>
    </joint>
</robot>