<?xml version="1.0"?>
<robot xmlns:xacro="http://www.ros.org/wiki/xacro" name="dream_car">
    <material name="white">
        <color rgba="1 1 1 1"/>
    </material>
    <material name="black">
        <color rgba="0 0 0 1"/>
    </material>

    <link name="base_link">
        <visual>
            <geometry>
                <box size="0.5 0.3 0.1"/>
            </geometry>
            <material name="white"/>
        </visual>
        <collision>
            <geometry>
                <box size="0.5 0.3 0.1"/>
            </geometry>
        </collision>
        <inertial>
            <mass value="2"/>
            <inertia ixx="0.1" ixy="0.0" ixz="0.0" iyy="0.1" iyz="0.0" izz="0.1"/>
        </inertial>
    </link>

    <link name="left_front_wheel">
        <visual>
            <origin rpy="1.5707 0 0"/>
            <geometry>
                <cylinder radius="0.05" length="0.04"/>
            </geometry>
            <material name="black"/>
        </visual>
        <collision>
            <origin rpy="1.5707 0 0"/>
            <geometry>
                <cylinder radius="0.05" length="0.04"/>
            </geometry>
        </collision>
    </link>

    <link name="left_back_wheel">
        <visual>
            <origin rpy="1.5707 0 0"/>
            <geometry>
                <cylinder radius="0.05" length="0.04"/>
            </geometry>
            <material name="black"/>
        </visual>
        <collision>
            <origin rpy="1.5707 0 0"/>
            <geometry>
                <cylinder radius="0.05" length="0.04"/>
            </geometry>
        </collision>
    </link>

    <link name="right_front_wheel">
        <visual>
            <origin rpy="1.5707 0 0"/>
            <geometry>
                <cylinder radius="0.05" length="0.04"/>
            </geometry>
            <material name="black"/>
        </visual>
        <collision>
            <origin rpy="1.5707 0 0"/>
            <geometry>
                <cylinder radius="0.05" length="0.04"/>
            </geometry>
        </collision>
    </link>

    <link name="right_back_wheel">
        <visual>
            <origin rpy="1.5707 0 0"/>
            <geometry>
                <cylinder radius="0.05" length="0.04"/>
            </geometry>
            <material name="black"/>
        </visual>
        <collision>
            <origin rpy="1.5707 0 0"/>
            <geometry>
                <cylinder radius="0.05" length="0.04"/>
            </geometry>
        </collision>
    </link>

    <link name="box">
        <visual>
            <geometry>
                <box size="0.02 0.02 0.02"/>
            </geometry>
        </visual>
        <collision>
            <geometry>
                <box size="0.02 0.02 0.02"/>
            </geometry>
        </collision>
    </link>

    <joint name="left_front_wheel_joint" type="continuous">
        <origin xyz="0.15 0.18 -0.03"/>
        <parent link="base_link"/>
        <child link="left_front_wheel"/>
        <axis xyz="0 1 0"/>
    </joint>

    <joint name="left_back_wheel_joint" type="continuous">
        <origin xyz="-0.15 0.18 -0.03"/>
        <parent link="base_link"/>
        <child link="left_back_wheel"/>
        <axis xyz="0 1 0"/>
    </joint>

    <joint name="right_front_wheel_joint" type="continuous">
        <origin xyz="0.15 -0.18 -0.03"/>
        <parent link="base_link"/>
        <child link="right_front_wheel"/>
        <axis xyz="0 1 0"/>
    </joint>

    <joint name="right_back_wheel_joint" type="continuous">
        <origin xyz="-0.15 -0.18 -0.03"/>
        <parent link="base_link"/>
        <child link="right_back_wheel"/>
        <axis xyz="0 1 0"/>
    </joint>

    <joint name="box_joint " type="fixed">
        <origin xyz="0.16 0.0 0.06"/>
        <parent link="base_link"/>
        <child link="box"/>
    </joint>

    <gazebo>
        <plugin name="gazebo_ros_control" filename="libgazebo_ros_control.so">
            <robotNamespace>/</robotNamespace>
        </plugin>
    </gazebo>

</robot>